<?xml version="1.0" ?>
<!-- =================================================================================== -->
<!-- |    This document was autogenerated by xacro from cubicbot.xacro                 | -->
<!-- |    EDITING THIS FILE BY HAND IS NOT RECOMMENDED                                 | -->
<!-- =================================================================================== -->
<robot name="cubicbot_urdf">
  <!-- Defining the colors used in this robot -->
  <material name="Black">
    <color rgba="0.0 0.0 0.0 1.0"/>
  </material>
  <material name="White">
    <color rgba="1.0 1.0 1.0 1.0"/>
  </material>
  <material name="Red">
    <color rgba="0.8 0.0 0.0 1.0"/>
  </material>
  <material name="Green">
    <color rgba="0.0 0.8 0.0 1.0"/>
  </material>
  <material name="Blue">
    <color rgba="0.0 0.0 0.8 1.0"/>
  </material>
  <!--kg-->
  <!--kg-->
  <!--kg-->
  <!-- Transmission is important to link the joints and the controller -->
  <!-- <transmission name="${lr}_wheel_joint_trans">
      <type>transmission_interface/SimpleTransmission</type>
      <joint name="${lr}_wheel_joint" />
      <actuator name="${lr}_wheel_joint_motor">
        <hardwareInterface>EffortJointInterface</hardwareInterface>
        <mechanicalReduction>1</mechanicalReduction>
      </actuator>
    </transmission> -->
  <link name="base_footprint"/>
  <!-- base_link -->
  <!--Actual body/chassis of the robot-->
  <link name="base_link">
    <inertial>
      <mass value="50"/>
      <origin xyz="0 0 0"/>
      <inertia ixx="2.0833333333333335" ixy="0" ixz="0" iyy="2.5416666666666665" iyz="0" izz="2.5416666666666665"/>
    </inertial>
    <visual>
      <origin rpy="0 0 0" xyz="0 0 0"/>
      <geometry>
        <box size="0.6 0.5 0.5"/>
      </geometry>
      <material name="transyellow">
        <color rgba="1.0 1.0 0.0 0.3"/>
      </material>
    </visual>
    <collision>
      <origin rpy="0 0 0 " xyz="0 0 0"/>
      <geometry>
        <box size="0.6 0.5 0.5"/>
      </geometry>
    </collision>
  </link>
  <!-- caster -->
  <!-- <link name="caster_link">
    <visual>
      <origin xyz="0 0 0" rpy="0 0 0" />
      <geometry>
	      <sphere radius="${caster_radius}" />
      </geometry>
      <material name="Black" />
    </visual>  
    <collision>
      <origin xyz="0 0 0" rpy="0 0 0" />
      <geometry>
	        <sphere radius="${caster_radius}" />
      </geometry>
    </collision>   
    <inertial>
      <mass value="${caster_mass}" />
      <origin xyz="0 0 0" />
      <inertia ixx="0.001" ixy="0.0" ixz="0.0"
               iyy="0.001" iyz="0.0" 
               izz="0.001" />
    </inertial>
  </link> -->
  <link name="imu_link">
    <visual>
      <origin rpy="0 0 0" xyz="0 0 0"/>
      <geometry>
        <box size="0.02 0.02 0.01"/>
      </geometry>
      <material name="Blue"/>
    </visual>
  </link>
  <link name="lidar_link">
    <visual>
      <origin rpy="0 0 0" xyz="0 0 0"/>
      <geometry>
        <cylinder length="0.05" radius="0.025"/>
      </geometry>
      <material name="Red"/>
    </visual>
  </link>
  <link name="camera_link">
    <visual>
      <origin rpy="0 0 0" xyz="0 0 0"/>
      <geometry>
        <box size="0.02 0.1 0.02"/>
      </geometry>
      <material name="Red"/>
    </visual>
  </link>
  <link name="depth_camera_link">
  </link>
  <joint name="base_joint" type="fixed">
    <parent link="base_footprint"/>
    <child link="base_link"/>
    <origin rpy="0 0 0" xyz="0 0 0.5"/>
  </joint>
  <!-- <joint name="caster_joint" type="fixed">
    <parent link="base_link"/>
    <child link="caster_link"/>
    <origin xyz="-0.15 0.0 -0.0465" rpy="0 0 0"/>
  </joint> -->
  <joint name="imu_joint" type="fixed">
    <parent link="base_link"/>
    <child link="imu_link"/>
    <origin rpy="0 0 0" xyz="0.0 0.0 -0.4"/>
  </joint>
  <joint name="lidar_joint" type="fixed">
    <parent link="base_link"/>
    <child link="lidar_link"/>
    <origin rpy="0 0 0" xyz="0 0 0.5"/>
    <!-- default z: -0.32 -->
  </joint>
  <joint name="camera_joint" type="fixed">
    <parent link="base_link"/>
    <child link="camera_link"/>
    <origin rpy="0 0 0" xyz="0.31 0 0"/>
  </joint>
  <joint name="depth_camera_joint" type="fixed">
    <parent link="base_link"/>
    <child link="depth_camera_link"/>
    <origin rpy="-1.570796327 0 -1.570796327" xyz="0.31 0 0"/>
  </joint>
  <!-- lr: left, right -->
  <link name="left_wheel_link">
    <visual>
      <origin rpy="0 0 0 " xyz="0 0 0"/>
      <geometry>
        <cylinder length="0.1" radius="0.07"/>
      </geometry>
      <material name="Black"/>
    </visual>
    <collision>
      <origin rpy="0 0 0 " xyz="0 0 0"/>
      <geometry>
        <cylinder length="0.1" radius="0.07"/>
      </geometry>
    </collision>
    <inertial>
      <mass value="2"/>
      <origin xyz="0 0 0"/>
      <inertia ixx="0.004116666666666668" ixy="0" ixz="0" iyy="0.004116666666666668" iyz="0" izz="0.004900000000000001"/>
    </inertial>
  </link>
  <joint name="left_wheel_joint" type="continuous">
    <parent link="base_link"/>
    <child link="left_wheel_link"/>
    <origin rpy="-1.570796327 0 0" xyz="0 0.2 -0.43"/>
    <axis xyz="0 0 1"/>
    <limit effort="100" velocity="100"/>
    <dynamics damping="0.0" friction="0.1"/>
  </joint>
  <!-- lr: left, right -->
  <link name="right_wheel_link">
    <visual>
      <origin rpy="0 0 0 " xyz="0 0 0"/>
      <geometry>
        <cylinder length="0.1" radius="0.07"/>
      </geometry>
      <material name="Black"/>
    </visual>
    <collision>
      <origin rpy="0 0 0 " xyz="0 0 0"/>
      <geometry>
        <cylinder length="0.1" radius="0.07"/>
      </geometry>
    </collision>
    <inertial>
      <mass value="2"/>
      <origin xyz="0 0 0"/>
      <inertia ixx="0.004116666666666668" ixy="0" ixz="0" iyy="0.004116666666666668" iyz="0" izz="0.004900000000000001"/>
    </inertial>
  </link>
  <joint name="right_wheel_joint" type="continuous">
    <parent link="base_link"/>
    <child link="right_wheel_link"/>
    <origin rpy="-1.570796327 0 0" xyz="0 -0.2 -0.43"/>
    <axis xyz="0 0 1"/>
    <limit effort="100" velocity="100"/>
    <dynamics damping="0.0" friction="0.1"/>
  </joint>
  <!-- fb: front, back -->
  <link name="front_caster_link">
    <visual>
      <origin rpy="0 0 0 " xyz="0 0 0"/>
      <geometry>
        <sphere radius="0.05"/>
      </geometry>
      <material name="Red"/>
    </visual>
    <collision>
      <origin rpy="0 0 0 " xyz="0 0 0"/>
      <geometry>
        <sphere radius="0.05"/>
      </geometry>
    </collision>
    <inertial>
      <mass value="1.0"/>
      <origin xyz="0 0 0"/>
      <inertia ixx="0.0010000000000000002" ixy="0" ixz="0" iyy="0.0010000000000000002" iyz="0" izz="0.0010000000000000002"/>
    </inertial>
  </link>
  <joint name="front_caster_joint" type="fixed">
    <parent link="base_link"/>
    <child link="front_caster_link"/>
    <origin rpy="0 0 0" xyz="0.25 0 -0.449"/>
    <axis rpy="0 0 0" xyz="1 1 1"/>
  </joint>
  <!-- fb: front, back -->
  <link name="back_caster_link">
    <visual>
      <origin rpy="0 0 0 " xyz="0 0 0"/>
      <geometry>
        <sphere radius="0.05"/>
      </geometry>
      <material name="Blue"/>
    </visual>
    <collision>
      <origin rpy="0 0 0 " xyz="0 0 0"/>
      <geometry>
        <sphere radius="0.05"/>
      </geometry>
    </collision>
    <inertial>
      <mass value="1.0"/>
      <origin xyz="0 0 0"/>
      <inertia ixx="0.0010000000000000002" ixy="0" ixz="0" iyy="0.0010000000000000002" iyz="0" izz="0.0010000000000000002"/>
    </inertial>
  </link>
  <joint name="back_caster_joint" type="fixed">
    <parent link="base_link"/>
    <child link="back_caster_link"/>
    <origin rpy="0 0 0" xyz="-0.25 0 -0.449"/>
    <axis rpy="0 0 0" xyz="1 1 1"/>
  </joint>
</robot>
