<?xml version="1.0" ?>
<!-- =================================================================================== -->
<!-- |    This document was autogenerated by xacro from cubicbot_gazebo.xacro          | -->
<!-- |    EDITING THIS FILE BY HAND IS NOT RECOMMENDED                                 | -->
<!-- =================================================================================== -->
<robot name="cubicbot_gazebo">
  <!-- Defining the colors used in this robot -->
  <material name="Black">
    <color rgba="0.0 0.0 0.0 1.0"/>
  </material>
  <material name="White">
    <color rgba="1.0 1.0 1.0 1.0"/>
  </material>
  <material name="Red">
    <color rgba="0.8 0.0 0.0 1.0"/>
  </material>
  <material name="Green">
    <color rgba="0.0 0.8 0.0 1.0"/>
  </material>
  <material name="Blue">
    <color rgba="0.0 0.0 0.8 1.0"/>
  </material>
  <!--kg-->
  <!--kg-->
  <!--kg-->
  <link name="base_footprint"/>
  <!-- base_link -->
  <!--Actual body/chassis of the robot-->
  <link name="base_link">
    <inertial>
      <mass value="50"/>
      <origin xyz="0 0 0"/>
      <inertia ixx="2.0833333333333335" ixy="0" ixz="0" iyy="2.5416666666666665" iyz="0" izz="2.5416666666666665"/>
    </inertial>
    <visual>
      <origin rpy="0 0 0" xyz="0 0 0"/>
      <geometry>
        <box size="0.6 0.5 0.5"/>
      </geometry>
      <material name="transyellow">
        <color rgba="1.0 1.0 0.0 0.3"/>
      </material>
    </visual>
    <collision>
      <origin rpy="0 0 0 " xyz="0 0 0"/>
      <geometry>
        <box size="0.6 0.5 0.5"/>
      </geometry>
    </collision>
  </link>
  <!-- caster -->
  <!-- <link name="caster_link">
    <visual>
      <origin xyz="0 0 0" rpy="0 0 0" />
      <geometry>
	      <sphere radius="${caster_radius}" />
      </geometry>
      <material name="Black" />
    </visual>  
    <collision>
      <origin xyz="0 0 0" rpy="0 0 0" />
      <geometry>
	        <sphere radius="${caster_radius}" />
      </geometry>
    </collision>   
    <inertial>
      <mass value="${caster_mass}" />
      <origin xyz="0 0 0" />
      <inertia ixx="0.001" ixy="0.0" ixz="0.0"
               iyy="0.001" iyz="0.0" 
               izz="0.001" />
    </inertial>
  </link> -->
  <link name="imu_link">
    <visual>
      <origin rpy="0 0 0" xyz="0 0 0"/>
      <geometry>
        <box size="0.02 0.02 0.01"/>
      </geometry>
      <material name="Blue"/>
    </visual>
  </link>
  <link name="lidar_link">
    <visual>
      <origin rpy="0 0 0" xyz="0 0 0"/>
      <geometry>
        <cylinder length="0.05" radius="0.025"/>
      </geometry>
      <material name="Red"/>
    </visual>
  </link>
  <link name="camera_link">
    <visual>
      <origin rpy="0 0 0" xyz="0 0 0"/>
      <geometry>
        <box size="0.02 0.1 0.02"/>
      </geometry>
      <material name="Red"/>
    </visual>
  </link>
  <link name="depth_camera_link">
  </link>
  <joint name="base_joint" type="fixed">
    <parent link="base_footprint"/>
    <child link="base_link"/>
    <origin rpy="0 0 0" xyz="0 0 0.5"/>
  </joint>
  <!-- <joint name="caster_joint" type="fixed">
    <parent link="base_link"/>
    <child link="caster_link"/>
    <origin xyz="-0.15 0.0 -0.0465" rpy="0 0 0"/>
  </joint> -->
  <joint name="imu_joint" type="fixed">
    <parent link="base_link"/>
    <child link="imu_link"/>
    <origin rpy="0 0 0" xyz="0.0 0.0 -0.4"/>
  </joint>
  <joint name="lidar_joint" type="fixed">
    <parent link="base_link"/>
    <child link="lidar_link"/>
    <origin rpy="0 0 0" xyz="0 0 0.5"/>
    <!-- default z: -0.32 -->
  </joint>
  <joint name="camera_joint" type="fixed">
    <parent link="base_link"/>
    <child link="camera_link"/>
    <origin rpy="0 0 0" xyz="0.31 0 0"/>
  </joint>
  <joint name="depth_camera_joint" type="fixed">
    <parent link="base_link"/>
    <child link="depth_camera_link"/>
    <origin rpy="-1.570796327 0 -1.570796327" xyz="0.31 0 0"/>
  </joint>
  <!-- lr: left, right -->
  <link name="left_wheel_link">
    <visual>
      <origin rpy="0 0 0 " xyz="0 0 0"/>
      <geometry>
        <cylinder length="0.1" radius="0.07"/>
      </geometry>
      <material name="Black"/>
    </visual>
    <collision>
      <origin rpy="0 0 0 " xyz="0 0 0"/>
      <geometry>
        <cylinder length="0.1" radius="0.07"/>
      </geometry>
    </collision>
    <inertial>
      <mass value="2"/>
      <origin xyz="0 0 0"/>
      <inertia ixx="0.004116666666666668" ixy="0" ixz="0" iyy="0.004116666666666668" iyz="0" izz="0.004900000000000001"/>
    </inertial>
  </link>
  <joint name="left_wheel_joint" type="continuous">
    <parent link="base_link"/>
    <child link="left_wheel_link"/>
    <origin rpy="-1.570796327 0 0" xyz="0 0.2 -0.43"/>
    <axis xyz="0 0 1"/>
    <limit effort="100" velocity="100"/>
    <dynamics damping="0.0" friction="0.1"/>
  </joint>
  <!-- lr: left, right -->
  <link name="right_wheel_link">
    <visual>
      <origin rpy="0 0 0 " xyz="0 0 0"/>
      <geometry>
        <cylinder length="0.1" radius="0.07"/>
      </geometry>
      <material name="Black"/>
    </visual>
    <collision>
      <origin rpy="0 0 0 " xyz="0 0 0"/>
      <geometry>
        <cylinder length="0.1" radius="0.07"/>
      </geometry>
    </collision>
    <inertial>
      <mass value="2"/>
      <origin xyz="0 0 0"/>
      <inertia ixx="0.004116666666666668" ixy="0" ixz="0" iyy="0.004116666666666668" iyz="0" izz="0.004900000000000001"/>
    </inertial>
  </link>
  <joint name="right_wheel_joint" type="continuous">
    <parent link="base_link"/>
    <child link="right_wheel_link"/>
    <origin rpy="-1.570796327 0 0" xyz="0 -0.2 -0.43"/>
    <axis xyz="0 0 1"/>
    <limit effort="100" velocity="100"/>
    <dynamics damping="0.0" friction="0.1"/>
  </joint>
  <!-- fb: front, back -->
  <link name="front_caster_link">
    <visual>
      <origin rpy="0 0 0 " xyz="0 0 0"/>
      <geometry>
        <sphere radius="0.05"/>
      </geometry>
      <material name="Red"/>
    </visual>
    <collision>
      <origin rpy="0 0 0 " xyz="0 0 0"/>
      <geometry>
        <sphere radius="0.05"/>
      </geometry>
    </collision>
    <inertial>
      <mass value="1.0"/>
      <origin xyz="0 0 0"/>
      <inertia ixx="0.0010000000000000002" ixy="0" ixz="0" iyy="0.0010000000000000002" iyz="0" izz="0.0010000000000000002"/>
    </inertial>
  </link>
  <joint name="front_caster_joint" type="fixed">
    <parent link="base_link"/>
    <child link="front_caster_link"/>
    <origin rpy="0 0 0" xyz="0.25 0 -0.449"/>
    <axis rpy="0 0 0" xyz="1 1 1"/>
  </joint>
  <!-- fb: front, back -->
  <link name="back_caster_link">
    <visual>
      <origin rpy="0 0 0 " xyz="0 0 0"/>
      <geometry>
        <sphere radius="0.05"/>
      </geometry>
      <material name="Blue"/>
    </visual>
    <collision>
      <origin rpy="0 0 0 " xyz="0 0 0"/>
      <geometry>
        <sphere radius="0.05"/>
      </geometry>
    </collision>
    <inertial>
      <mass value="1.0"/>
      <origin xyz="0 0 0"/>
      <inertia ixx="0.0010000000000000002" ixy="0" ixz="0" iyy="0.0010000000000000002" iyz="0" izz="0.0010000000000000002"/>
    </inertial>
  </link>
  <joint name="back_caster_joint" type="fixed">
    <parent link="base_link"/>
    <child link="back_caster_link"/>
    <origin rpy="0 0 0" xyz="-0.25 0 -0.449"/>
    <axis rpy="0 0 0" xyz="1 1 1"/>
  </joint>
  <!-- gazebo reference="xxx_link" 是指给xxx_link赋予属性(颜色,摩擦力等)或添加插件(传感器,控制等)-->
  <gazebo reference="camera_link">
    <material>Gazebo/Red</material>
  </gazebo>
  <gazebo reference="base_link">
    <material>Gazebo/Yellow</material>
    <visual>
      <transparency>0.3</transparency>
    </visual>
  </gazebo>
  <gazebo reference="left_wheel_link">
    <mu1>1</mu1>
    <mu2>1</mu2>
    <kp>100000.0</kp>
    <kd>10.0</kd>
    <minDepth>0.001</minDepth>
    <maxVel>2.0</maxVel>
    <fdir1>1 0 0</fdir1>
    <material>Gazebo/FlatBlack</material>
    <!--replace color setting in essential.xacro, default color in essential-->
  </gazebo>
  <gazebo reference="right_wheel_link">
    <mu1>1</mu1>
    <mu2>1</mu2>
    <kp>100000.0</kp>
    <kd>10.0</kd>
    <minDepth>0.001</minDepth>
    <maxVel>2.0</maxVel>
    <fdir1>1 0 0</fdir1>
    <material>Gazebo/FlatBlack</material>
  </gazebo>
  <gazebo reference="front_caster_link">
    <mu1>0.1</mu1>
    <mu2>0.1</mu2>
    <kp>1000000.0</kp>
    <kd>100.0</kd>
    <minDepth>0.001</minDepth>
    <maxVel>1.0</maxVel>
    <material>Gazebo/Red</material>
  </gazebo>
  <gazebo reference="back_caster_link">
    <mu1>0.1</mu1>
    <mu2>0.1</mu2>
    <kp>1000000.0</kp>
    <kd>100.0</kd>
    <minDepth>0.001</minDepth>
    <maxVel>1.0</maxVel>
    <material>Gazebo/Blue</material>
  </gazebo>
  <gazebo reference="imu_link">
    <material>Gazebo/Green</material>
    <sensor name="imu_sensor" type="imu">
      <!-- ensure the sensor is active (required) -->
      <always_on>true</always_on>
      <update_rate>100</update_rate>
      <plugin filename="libgazebo_ros_imu_sensor.so" name="imu_plugin">
        <ros>
          <!-- publish to /imu/data -->
          <!-- <namespace>/imu</namespace>
          <remapping>~/out:=data</remapping> -->
          <remapping>~/out:=imu_data</remapping>
        </ros>
      </plugin>
    </sensor>
  </gazebo>
  <gazebo reference="lidar_link">
    <material>Gazebo/Red</material>
    <sensor name="lidar_sensor" type="ray">
      <always_on>true</always_on>
      <visualize>true</visualize>
      <pose>0 0 0 0 0 0</pose>
      <update_rate>10</update_rate>
      <ray>
        <scan>
          <horizontal>
            <samples>360</samples>
            <resolution>1.000000</resolution>
            <min_angle>0.000000</min_angle>
            <max_angle>6.280000</max_angle>
          </horizontal>
        </scan>
        <range>
          <min>0.120000</min>
          <max>25.0</max>
          <resolution>0.015000</resolution>
        </range>
        <noise>
          <type>gaussian</type>
          <mean>0.0</mean>
          <stddev>0.01</stddev>
        </noise>
      </ray>
      <plugin filename="libgazebo_ros_ray_sensor.so" name="lidar_plugin">
        <ros>
          <!-- <namespace>/scan</namespace>
            <remapping>~/out:=data</remapping> -->
          <remapping>~/out:=scan</remapping>
        </ros>
        <output_type>sensor_msgs/LaserScan</output_type>
        <frame_name>lidar_link</frame_name>
      </plugin>
    </sensor>
  </gazebo>
  <gazebo>
    <plugin filename="libgazebo_ros_diff_drive.so" name="gazebo_ros_diff_drive">
      <!-- Update rate in Hz -->
      <update_rate>50</update_rate>
      <!-- wheels -->
      <left_joint>left_wheel_joint</left_joint>
      <right_joint>right_wheel_joint</right_joint>
      <!-- kinematics -->
      <wheel_separation>0.4</wheel_separation>
      <wheel_diameter>0.14</wheel_diameter>
      <!-- limits -->
      <max_wheel_torque>20</max_wheel_torque>
      <max_wheel_acceleration>1.0</max_wheel_acceleration>
      <!-- input -->
      <command_topic>cmd_vel</command_topic>
      <!-- output -->
      <publish_odom>true</publish_odom>
      <publish_odom_tf>true</publish_odom_tf>
      <publish_wheel_tf>false</publish_wheel_tf>
      <odometry_topic>odom</odometry_topic>
      <odometry_frame>odom</odometry_frame>
      <robot_base_frame>base_footprint</robot_base_frame>
      <!-- will pub tf between /odom and /base_footprint-->
    </plugin>
  </gazebo>
</robot>
