<?xml version="1.0" ?>
<!-- =================================================================================== -->
<!-- |    This document was autogenerated by xacro from demobot_urdf.xacro             | -->
<!-- |    EDITING THIS FILE BY HAND IS NOT RECOMMENDED                                 | -->
<!-- =================================================================================== -->
<robot name="demobot_urdf">
  <!-- Defining the colors used in this robot -->
  <material name="Black">
    <color rgba="0.0 0.0 0.0 1.0"/>
  </material>
  <material name="White">
    <color rgba="1.0 1.0 1.0 1.0"/>
  </material>
  <material name="Red">
    <color rgba="0.8 0.0 0.0 1.0"/>
  </material>
  <material name="Green">
    <color rgba="0.0 0.8 0.0 1.0"/>
  </material>
  <material name="Blue">
    <color rgba="0.0 0.0 0.8 1.0"/>
  </material>
  <!--kg-->
  <!--kg-->
  <!--box_inertia-->
  <!--sphere_inertia-->
  <link name="base_footprint"/>
  <!-- base_link -->
  <!--Actual body/chassis of the robot-->
  <link name="base_link">
    <!-- <inertial>
      <mass value="${base_mass}" />
      <origin xyz="0 0 0" />
        <box_inertia  />
    </inertial>     -->
    <visual>
      <origin rpy="0 0 0" xyz="0 0 0"/>
      <geometry>
        <!-- <box size="${base_length} ${base_width} ${base_height}" /> -->
        <mesh filename="package://demobot2_description/meshes/demobot/body.stl"/>
      </geometry>
      <material name="White"/>
    </visual>
    <collision>
      <origin rpy="0 0 0 " xyz="0 0 0"/>
      <geometry>
        <box size="0.24 0.2 0.02"/>
      </geometry>
    </collision>
  </link>
  <!-- caster -->
  <link name="caster_link">
    <visual>
      <origin rpy="0 0 0" xyz="0 0 0"/>
      <geometry>
        <sphere radius="0.01"/>
      </geometry>
      <material name="Black"/>
    </visual>
    <collision>
      <origin rpy="0 0 0" xyz="0 0 0"/>
      <geometry>
        <sphere radius="0.01"/>
      </geometry>
    </collision>
    <inertial>
      <mass value="0.1"/>
      <origin xyz="0 0 0"/>
      <inertia ixx="0.001" ixy="0.0" ixz="0.0" iyy="0.001" iyz="0.0" izz="0.001"/>
    </inertial>
  </link>
  <link name="imu_link">
    <visual>
      <origin rpy="0 0 0" xyz="0 0 0"/>
      <geometry>
        <box size="0.02 0.02 0.01"/>
      </geometry>
      <material name="Blue"/>
    </visual>
  </link>
  <link name="lidar_link">
    <visual>
      <origin rpy="0 0 0" xyz="0 0 0"/>
      <geometry>
        <cylinder length="0.05" radius="0.025"/>
      </geometry>
      <material name="Red"/>
    </visual>
  </link>
  <joint name="base_joint" type="fixed">
    <parent link="base_footprint"/>
    <child link="base_link"/>
    <origin rpy="0 0 0" xyz="0 0 00.0565"/>
  </joint>
  <joint name="caster_joint" type="fixed">
    <parent link="base_link"/>
    <child link="caster_link"/>
    <origin rpy="0 0 0" xyz="-0.15 0.0 -0.0465"/>
  </joint>
  <joint name="imu_joint" type="fixed">
    <parent link="base_link"/>
    <child link="imu_link"/>
    <origin rpy="0 0 0" xyz="0.0 0.0 0.075"/>
  </joint>
  <joint name="lidar_joint" type="fixed">
    <parent link="base_link"/>
    <child link="lidar_link"/>
    <!-- <origin xyz="0 0 0.105" rpy="0 0 0"/> -->
    <origin rpy="0 0 0" xyz="0 0 0.3"/>
  </joint>
  <!-- lr: left, right -->
  <link name="left_wheel_link">
    <visual>
      <origin rpy="0 0 0 " xyz="0 0 0"/>
      <geometry>
        <!-- <cylinder length="${wheel_height}" radius="${wheel_radius}" /> -->
        <mesh filename="package://demobot2_description/meshes/demobot/wheel.stl"/>
      </geometry>
      <material name="Black"/>
    </visual>
    <collision>
      <origin rpy="0 0 0 " xyz="0 0 0"/>
      <geometry>
        <cylinder length="0.035" radius="0.0365"/>
      </geometry>
    </collision>
    <inertial>
      <mass value="0.25"/>
      <origin xyz="0 0 0"/>
      <inertia ixx="0.00010878645833333333" ixy="0" ixz="0" iyy="0.00010878645833333333" iyz="0" izz="0.00016653124999999999"/>
    </inertial>
  </link>
  <joint name="left_wheel_joint" type="continuous">
    <parent link="base_link"/>
    <child link="left_wheel_link"/>
    <origin rpy="-1.570796327 0 0" xyz="0 0.0865 -0.02"/>
    <axis xyz="0 0 1"/>
    <limit effort="100" velocity="100"/>
    <dynamics damping="0.0" friction="0.1"/>
  </joint>
  <!-- lr: left, right -->
  <link name="right_wheel_link">
    <visual>
      <origin rpy="0 0 0 " xyz="0 0 0"/>
      <geometry>
        <!-- <cylinder length="${wheel_height}" radius="${wheel_radius}" /> -->
        <mesh filename="package://demobot2_description/meshes/demobot/wheel.stl"/>
      </geometry>
      <material name="Black"/>
    </visual>
    <collision>
      <origin rpy="0 0 0 " xyz="0 0 0"/>
      <geometry>
        <cylinder length="0.035" radius="0.0365"/>
      </geometry>
    </collision>
    <inertial>
      <mass value="0.25"/>
      <origin xyz="0 0 0"/>
      <inertia ixx="0.00010878645833333333" ixy="0" ixz="0" iyy="0.00010878645833333333" iyz="0" izz="0.00016653124999999999"/>
    </inertial>
  </link>
  <joint name="right_wheel_joint" type="continuous">
    <parent link="base_link"/>
    <child link="right_wheel_link"/>
    <origin rpy="-1.570796327 0 0" xyz="0 -0.0865 -0.02"/>
    <axis xyz="0 0 1"/>
    <limit effort="100" velocity="100"/>
    <dynamics damping="0.0" friction="0.1"/>
  </joint>
</robot>
